Workbook

Sheet Read Me
B2: NYOD — GTM & Weekly Forecast Model (Jul 2026 – Jun 2027)
B4: Built for: The NYOD GTM Challenge (₹2.5L → ₹1cr MRR in 12 months)
B6: HOW THIS WORKBOOK IS ORGANISED
B7: 1. Assumptions & Log — every driver, its Base/Bull/Bear value, and the rationale. Change the scenario switch (cell C3) to Base, Bull or Bear and the entire model recalculates.
B8: 2. Monthly Engine — the driver tree: spend → CAC → orders → repeat/subscription → revenue → cans → CM1/CM2 → EBITDA → cash, one column per month, fully formula-linked to Assumptions.
B9: 3. Weekly Rollout — 52 weekly rows (Jul 1, 2026 – Jun 29, 2027). Each week = its month's Monthly Engine total x a within-month weight (weights sum to 1, so weekly rows always tie back to the monthly engine exactly).
B10: 4. Monthly Rollup & Cash — the path to Rs 1cr MRR, capacity vs cans required, batch orders, and the running cash balance against the Rs 5L covenant floor.
B11: 5. Scenario Comparison — Base / Bull / Bear side-by-side (computed by running the engine under each scenario). Reference snapshot; recreate live by switching the toggle on the Assumptions tab.
B12: 6. Sensitivity — Month-12 revenue sensitivity to the 3 assumptions the outcome is most exposed to.
B14: KEY MODELLING CHOICES (see Assumptions & Log tab for full detail + rationale):
B15: - Weekly rows disaggregate monthly cohort/subscription dynamics evenly across the weeks of a month; only new-customer acquisition (paid+organic) carries week-specific nudges for named calendar events (Diwali week, New Year gut-health spike week).
B16: - 'MRR' = monthly net revenue run-rate, per the founders' usage (brief, Sec 9). Only Subscribe & Save is contractually recurring; this is called out wherever relevant.
... B18: - Blue text = hardcoded input/assumption. Black = formula. Green = cross-sheet link.

Sheet Assumptions & Log
A1: ASSUMPTIONS, SCENARIO SWITCH & ASSUMPTION LOG
A3: SCENARIO SWITCH: | B3: Base | C3: <- change this cell to Base / Bull / Bear. Everything downstream recalculates.
A5: Key | B5: Driver / Assumption | C5: Base | D5: Bull | E5: Bear | F5: Active | G5: Rationale | H5: Source / Basis
A6: cash0 | B6: Opening cash, Jul 1 2026 (₹) | C6: 3140000 | D6: 3140000 | E6: 3140000 | F6: =CHOOSE(MATCH($B$3,{"Base","Bull","Bear"},0),C6,D6,E6) -> 3140000 | G6: Founders' cash position at close of the data-pack period. | H6: Data pack: Financial Position, Jun 30 2026
A7: cac0 | B7: Opening blended paid CAC, Jul 2026 (₹) | C7: 536.5 | D7: 536.5 | E7: 536.5 | F7: =CHOOSE(MATCH($B$3,{"Base","Bull","Bear"},0),C7,D7,E7) -> 536.5 | G7: June actual blended paid CAC (Meta+Google spend ÷ Meta+Google last-click orders). | H7: Data pack: Channel Performance, June 2026
A8: cum_cust0 | B8: Cumulative D2C customers as of Jun 30, 2026 | C8: 488 | D8: 488 | E8: 488 | F8: =CHOOSE(MATCH($B$3,{"Base","Bull","Bear"},0),C8,D8,E8) -> 488 | G8: May cohort (223) + June new customers (265). | H8: Data pack: Retention & Subs
A9: subs0 | B9: Active subscribers, Jun 30 2026 | C9: 47 | D9: 47 | E9: 47 | F9: =CHOOSE(MATCH($B$3,{"Base","Bull","Bear"},0),C9,D9,E9) -> 47 | G9: Given directly. | H9: Data pack: Retention & Subs
A10: capacity0 | B10: Starting capacity ceiling (cans/month) | C10: 48000 | D10: 48000 | E10: 48000 | F10: =CHOOSE(MATCH($B$3,{"Base","Bull","Bear"},0),C10,D10,E10) -> 48000 | G10: Co-packer MOQ 24,000/batch x 2 batches/month max on current line. | H10: Founder Notes #10
A12: paid_spend0 | B12: Opening monthly paid spend, Jul-26 (₹) | C12: 115000 | D12: 135000 | E12: 100000 | F12: =CHOOSE(MATCH($B$3,{"Base","Bull","Bear"},0),C12,D12,E12) -> 115000 | G12: Base holds spend growth close to June's trajectory; Bull front-loads spend assuming a Q3 funding top-up is likely; Bear assumes founders get cautious after a weak July.
A13: paid_g_hi | B13: Monthly paid-spend growth, high-demand months | C13: 0.16 | D13: 0.21 | E13: 0.07 | F13: =CHOOSE(MATCH($B$3,{"Base","Bull","Bear"},0),C13,D13,E13) -> 0.16 | G13: Applied in months where the seasonality index >= June-2026 reference (festive/summer). Bull pushes harder into tailwind months; Bear conserves cash. | H13: Derived: May->Jun Meta+Google spend grew +47% WoW-ish during scale-up; tapered down for realism post fund-constrained periods.
A14: paid_g_lo | B14: Monthly paid-spend growth, low-demand months | C14: 0.05 | D14: 0.09 | E14: 0.01 | F14: =CHOOSE(MATCH($B$3,{"Base","Bull","Bear"},0),C14,D14,E14) -> 0.05 | G14: Applied Jul-Sep monsoon and Dec-Feb winter troughs — spend still grows (new creative, retargeting) but far slower than peak season.
A15: cac_drift | B15: Structural monthly CAC inflation (pre-relief) | C15: 0.014 | D15: 0.012 | E15: 0.026 | F15: =CHOOSE(MATCH($B$3,{"Base","Bull","Bear"},0),C15,D15,E15) -> 0.014 | G15: Reflects rising CPMs/frequency on a single-creative Meta account (May->Jun CAC actually rose from ₹448->536, +19.7% in one month) and increasing competitive intensity in the RTD/functional-drinks category. | H15: Data pack: Channel Performance MoM CAC; Founder Notes #8 (CPM +22%, frequency 3.8)
A16: cac_relief_m | B16: Month index (0=Jul-26) when creative-refresh programme lands | C16: 3 | D16: 2 | E16: 6 | F16: =CHOOSE(MATCH($B$3,{"Base","Bull","Bear"},0),C16,D16,E16) -> 3 | G16: A dedicated content/creative hire (see hiring plan) is assumed to break the single-creative fatigue loop. Bull hires faster; Bear delays because of cash stress.
A17: cac_relief | B17: Structural monthly CAC inflation, post-relief | C17: 0.005 | D17: 0.006 | E17: 0.004 | F17: =CHOOSE(MATCH($B$3,{"Base","Bull","Bear"},0),C17,D17,E17) -> 0.005 | G17: Even with more creative throughput, category CPCs keep rising as more D2C brands enter; relief only partially offsets drift.
A18: referral_rate | B18: Monthly organic referrals as % of cumulative customer base | C18: 0.028 | D18: 0.045 | E18: 0.012 | F18: =CHOOSE(MATCH($B$3,{"Base","Bull","Bear"},0),C18,D18,E18) -> 0.028 | G18: Organic (non-paid, non-content) orders = referral_rate x cumulative customers, i.e. a WOM/network effect that compounds as the customer base grows. Calibrated so June's actual organic share (103 of 303 orders, ~34%) is the starting order of magnitude, then let it compound. | H18: Data pack: Channel Performance (Organic+Direct+SEO+CRM = 103 of 303 June orders)
A19: content_baseline | B19: Baseline monthly organic/content orders (demand-adjusted) | C19: 25 | D19: 40 | E19: 10 | F19: =CHOOSE(MATCH($B$3,{"Base","Bull","Bear"},0),C19,D19,E19) -> 25 | G19: SEO, content and CRM-driven orders that don't scale off the referral network effect — floor demand independent of paid spend.
A20: repeat_prob_start | B20: Monthly repeat-purchase probability, Jul-26 | C20: 0.16 | D20: 0.17 | E20: 0.11 | F20: =CHOOSE(MATCH($B$3,{"Base","Bull","Bear"},0),C20,D20,E20) -> 0.16 | G20: Applied to the pool of customers acquired 1-2 months prior (D2C repeat cohort, excluding subscribers). May-cohort actuals show 15.2% repurchased within ~45 days — used as the anchor. | H20: Data pack: Retention & Subs (May cohort, 15.2% repurchase by Jun 30, avg 26 days to 2nd order)
A21: repeat_prob_end | B21: Monthly repeat-purchase probability, Jun-27 | C21: 0.24 | D21: 0.3 | E21: 0.15 | F21: =CHOOSE(MATCH($B$3,{"Base","Bull","Bear"},0),C21,D21,E21) -> 0.24 | G21: Assumes lifecycle email/WhatsApp flows, loyalty perks and better PDP trust signals lift repeat behaviour over 12 months — a common D2C trajectory as retention programmes mature.
A22: sub_share_start | B22: Share of new customers opting into Subscribe&Save, Jul-26 | C22: 0.09 | D22: 0.1 | E22: 0.07 | F22: =CHOOSE(MATCH($B$3,{"Base","Bull","Bear"},0),C22,D22,E22) -> 0.09 | G22: June actual was already 8% of orders within 3 weeks of launch (Jun 10). Assume slight uptick as it becomes a default checkout nudge. | H22: Data pack: Retention & Subs (8% of June orders)
A23: sub_share_end | B23: Share of new customers opting into Subscribe&Save, Jun-27 | C23: 0.24 | D23: 0.32 | E23: 0.13 | F23: =CHOOSE(MATCH($B$3,{"Base","Bull","Bear"},0),C23,D23,E23) -> 0.24 | G23: Assumes active pack-architecture/pricing nudges toward subscription (10% discount + convenience) become a core PLG lever.
A24: sub_renewal | B24: Monthly subscription renewal rate | C24: 0.8 | D24: 0.84 | E24: 0.66 | F24: =CHOOSE(MATCH($B$3,{"Base","Bull","Bear"},0),C24,D24,E24) -> 0.8 | G24: No renewal data exists yet (first renewals due Jul 10). Benchmarked to typical D2C subscribe&save monthly renewal of 70-85%; Bear assumes renewal disappoints badly. | H24: Assumption — flagged as unknown in data pack (Retention & Subs: 'renewal rate unknown — you must assume one')
A25: aov_drift | B25: Monthly AOV growth (price + pack-mix upsize) | C25: 0.011 | D25: 0.016 | E25: 0.004 | F25: =CHOOSE(MATCH($B$3,{"Base","Bull","Bear"},0),C25,D25,E25) -> 0.011 | G25: Combines a modest price increase (allowed per brief Sec.4, pack/pricing changes permitted with justification) with mix-shift toward 12-packs/Subscribe (already the repeat-buyer pattern per Retention & Subs). | H25: Data pack: Retention & Subs ('repeat customers upsize to 12-packs')
A26: mkt_launch | B26: Month index Amazon marketplace goes live | C26: 1 | D26: 1 | E26: 2 | F26: =CHOOSE(MATCH($B$3,{"Base","Bull","Bear"},0),C26,D26,E26) -> 1 | G26: Beverage-compliance + FBA onboarding takes ~4 weeks per the founders' consultant; decision made in Jul, live by Aug (Base/Bull) or Sep (Bear, if deprioritised). | H26: Founder Notes #2 (not listed on Amazon; ~4-week onboarding)
A27: mkt_aov | B27: Marketplace (Amazon) AOV, ₹ | C27: 680 | D27: 700 | E27: 650 | F27: =CHOOSE(MATCH($B$3,{"Base","Bull","Bear"},0),C27,D27,E27) -> 680 | G27: Marketplace baskets skew smaller than D2C site baskets (single mid-pack SKU behaviour is typical on marketplaces).
A28: mkt_take | B28: Marketplace referral/fee take-rate | C28: 0.15 | D28: 0.15 | E28: 0.15 | F28: =CHOOSE(MATCH($B$3,{"Base","Bull","Bear"},0),C28,D28,E28) -> 0.15 | G28: Approximate Amazon beverage-category referral fee. | H28: Category benchmark (Amazon India seller fee schedule, beverages ~15%)
A29: mkt_add | B29: Marketplace monthly order-growth increment | C29: 110 | D29: 170 | E29: 40 | F29: =CHOOSE(MATCH($B$3,{"Base","Bull","Bear"},0),C29,D29,E29) -> 110 | G29: Additive new marketplace orders/month once live, scaled by the seasonality index.
A30: qc_launch | B30: Month index Quick-Commerce (Blinkit) pilot goes live | C30: 2 | D30: 1 | E30: 99 | F30: =CHOOSE(MATCH($B$3,{"Base","Bull","Bear"},0),C30,D30,E30) -> 2 | G30: Blinkit's inbound (2-city pilot, Jun 24) is accepted in Base/Bull after a short negotiation on trade terms; Bear assumes NYOD declines/delays the pilot to conserve cash and management bandwidth. | H30: Founder Notes #1 (Blinkit inbound: 18-22% trade margin, ~₹2L upfront, fortnightly replenishment)
A31: qc_aov | B31: Quick-commerce basket AOV, ₹ | C31: 520 | D31: 540 | E31: 500 | F31: =CHOOSE(MATCH($B$3,{"Base","Bull","Bear"},0),C31,D31,E31) -> 520 | G31: Quick-commerce baskets are impulse-sized — smaller than D2C or even marketplace.
A32: qc_take | B32: Quick-commerce trade margin to platform | C32: 0.2 | D32: 0.2 | E32: 0.2 | F32: =CHOOSE(MATCH($B$3,{"Base","Bull","Bear"},0),C32,D32,E32) -> 0.2 | G32: Midpoint of the Blinkit-quoted 18-22% trade margin range. | H32: Founder Notes #1
A33: qc_add | B33: Quick-commerce monthly order-growth increment | C33: 90 | D33: 160 | E33: 0 | F33: =CHOOSE(MATCH($B$3,{"Base","Bull","Bear"},0),C33,D33,E33) -> 90 | G33: Additive QC orders/month once live (2-city pilot: Delhi NCR + Bangalore, NYOD's #1 and #2 metros by order share). | H33: Founder Notes #7 (Delhi NCR 28%, Bangalore 19% of orders)
A34: exp2_m | B34: Month index capacity expansion #2 is COMMITTED | C34: 1 | D34: 0 | E34: 99 | F34: =CHOOSE(MATCH($B$3,{"Base","Bull","Bear"},0),C34,D34,E34) -> 1 | G34: A 2nd co-packer line (~₹6L capex, 60-75 day lead) is ordered in Aug-26 (Base) or immediately in Jul-26 (Bull) to be ready ahead of the Oct-Nov festive peak. Bear never commits — demand never requires it. | H34: Founder Notes #10 (2nd line: 60-75 days, ~₹6L)
A35: exp2_lead | B35: Lead time for expansion #2 (months, rounded) | C35: 2 | D35: 2 | E35: 3 | F35: =CHOOSE(MATCH($B$3,{"Base","Bull","Bear"},0),C35,D35,E35) -> 2 | G35: 60-75 days ≈ 2-2.5 months; Bear assumes a slower vendor process given lower urgency.
A36: exp3_m | B36: Month index capacity expansion #3 is COMMITTED (99=never) | C36: 7 | D36: 5 | E36: 99 | F36: =CHOOSE(MATCH($B$3,{"Base","Bull","Bear"},0),C36,D36,E36) -> 7 | G36: A 3rd line/co-packer is only committed in Bull, once Q2 festive results and Bull-case funding (see raise) de-risk the capex.
A37: exp3_lead | B37: Lead time for expansion #3 (months) | C37: 3 | D37: 3 | E37: 3 | F37: =CHOOSE(MATCH($B$3,{"Base","Bull","Bear"},0),C37,D37,E37) -> 3
A39: OPERATING & COST ASSUMPTIONS (same across scenarios unless noted)
A40: Key | B40: Driver / Assumption | C40: Base | D40: Bull | E40: Bear | F40: Active | G40: Rationale | H40: Source / Basis
A41: cogs_can_start | B41: COGS per can, Jul-26 (₹) | C41: 52 | D41: 52 | E41: 52 | F41: =CHOOSE(MATCH($B$3,{"Base","Bull","Bear"},0),C41,D41,E41) -> 52 | G41: Unchanged from June actual (₹28 ingredients + ₹16 can/label + ₹8 co-packer fee). | H41: Data pack: Monthly P&L unit-economics inputs
A42: cogs_can_end | B42: COGS per can, Jun-27 (₹) | C42: 47 | D42: 45 | E42: 50 | F42: =CHOOSE(MATCH($B$3,{"Base","Bull","Bear"},0),C42,D42,E42) -> 47 | G42: Modest volume-driven co-packer renegotiation as batch volumes scale; Bear assumes no leverage since volumes stay low.
A43: ship_ord_start | B43: Shipping per order, Jul-26 (₹) | C43: 76 | D43: 76 | E43: 76 | F43: =CHOOSE(MATCH($B$3,{"Base","Bull","Bear"},0),C43,D43,E43) -> 76 | G43: June actual. | H43: Data pack: Monthly P&L unit-economics inputs
A44: ship_ord_end | B44: Shipping per order, Jun-27 (₹) | C44: 64 | D44: 60 | E44: 72 | F44: =CHOOSE(MATCH($B$3,{"Base","Bull","Bear"},0),C44,D44,E44) -> 64 | G44: Freight consolidation / carrier renegotiation at higher volumes.
...

Sheet Monthly Engine
B1: MONTHLY DRIVER ENGINE (fully linked to Assumptions & Log — switch scenario there)
B3: Month index (0 = Jul-26) | C3: 0 | D3: 1 | E3: 2 | F3: 3 | G3: 4 | H3: 5 | I3: 6 | J3: 7 | K3: 8 | L3: 9 | M3: 10 | N3: 11
B4: Month | C4: Jul-26 | D4: Aug-26 | E4: Sep-26 | F4: Oct-26 | G4: Nov-26 | H4: Dec-26 | I4: Jan-27 | J4: Feb-27 | K4: Mar-27 | L4: Apr-27 | M4: May-27 | N4: Jun-27
B5: RTD/functional-beverage demand index | C5: 96 | D5: 88 | E5: 92 | F5: 108 | G5: 104 | H5: 84 | I5: 78 | J5: 82 | K5: 98 | L5: 122 | M5: 132 | N5: 128
B6: Gut-health interest index | C6: 94 | D6: 92 | E6: 96 | F6: 98 | G6: 96 | H6: 94 | I6: 126 | J6: 108 | K6: 100 | L6: 102 | M6: 98 | N6: 96
B7: Demand multiplier (vs Jun-26 baseline) | C7: =(0.75*C5+0.25*C6)/(0.75*128+0.25*96) -> 0.79583333 | D7: =(0.75*D5+0.25*D6)/(0.75*128+0.25*96) -> 0.74166667 | E7: =(0.75*E5+0.25*E6)/(0.75*128+0.25*96) -> 0.775 | F7: =(0.75*F5+0.25*F6)/(0.75*128+0.25*96) -> 0.87916667 | G7: =(0.75*G5+0.25*G6)/(0.75*128+0.25*96) -> 0.85 | H7: =(0.75*H5+0.25*H6)/(0.75*128+0.25*96) -> 0.72083333 | I7: =(0.75*I5+0.25*I6)/(0.75*128+0.25*96) -> 0.75 | J7: =(0.75*J5+0.25*J6)/(0.75*128+0.25*96) -> 0.7375 | ... N7: =(0.75*N5+0.25*N6)/(0.75*128+0.25*96) -> 1
B9: ACQUISITION & CAC
B10: Paid media spend (Meta+Google), ₹ | C10: ='Assumptions & Log'!$F$12 -> 115000 | D10: =C10*(1+IF(D7>=1,'Assumptions & Log'!$F$13,'Assumptions & Log'!$F$14))*IF(C67<'Assumptions & Log'!$F$57,0.85,1) -> 120750 | E10: =D10*(1+IF(E7>=1,'Assumptions & Log'!$F$13,'Assumptions & Log'!$F$14))*IF(D67<'Assumptions & Log'!$F$57,0.85,1) -> 126787.5 | F10: =E10*(1+IF(F7>=1,'Assumptions & Log'!$F$13,'Assumptions & Log'!$F$14))*IF(E67<'Assumptions & Log'!$F$57,0.85,1) -> 133126.88 | G10: =F10*(1+IF(G7>=1,'Assumptions & Log'!$F$13,'Assumptions & Log'!$F$14))*IF(F67<'Assumptions & Log'!$F$57,0.85,1) -> 139783.22 | H10: =G10*(1+IF(H7>=1,'Assumptions & Log'!$F$13,'Assumptions & Log'!$F$14))*IF(G67<'Assumptions & Log'!$F$57,0.85,1) -> 146772.38 | I10: =H10*(1+IF(I7>=1,'Assumptions & Log'!$F$13,'Assumptions & Log'!$F$14))*IF(H67<'Assumptions & Log'!$F$57,0.85,1) -> 154111 | J10: =I10*(1+IF(J7>=1,'Assumptions & Log'!$F$13,'Assumptions & Log'!$F$14))*IF(I67<'Assumptions & Log'!$F$57,0.85,1) -> 161816.55 | K10: =J10*(1+IF(K7>=1,'Assumptions & Log'!$F$13,'Assumptions & Log'!$F$14))*IF(J67<'Assumptions & Log'!$F$57,0.85,1) -> 169907.38 | ... N10: =M10*(1+IF(N7>=1,'Assumptions & Log'!$F$13,'Assumptions & Log'!$F$14))*IF(M67<'Assumptions & Log'!$F$57,0.85,1) -> 240058.73
B11: CAC structural trend (pre-seasonality), ₹ | C11: ='Assumptions & Log'!$F$7 -> 536.5 | D11: =C11*(1+IF(D3<'Assumptions & Log'!$F$16,'Assumptions & Log'!$F$15,'Assumptions & Log'!$F$17)) -> 544.011 | E11: =D11*(1+IF(E3<'Assumptions & Log'!$F$16,'Assumptions & Log'!$F$15,'Assumptions & Log'!$F$17)) -> 551.62715 | F11: =E11*(1+IF(F3<'Assumptions & Log'!$F$16,'Assumptions & Log'!$F$15,'Assumptions & Log'!$F$17)) -> 554.38529 | G11: =F11*(1+IF(G3<'Assumptions & Log'!$F$16,'Assumptions & Log'!$F$15,'Assumptions & Log'!$F$17)) -> 557.15722 | H11: =G11*(1+IF(H3<'Assumptions & Log'!$F$16,'Assumptions & Log'!$F$15,'Assumptions & Log'!$F$17)) -> 559.943 | I11: =H11*(1+IF(I3<'Assumptions & Log'!$F$16,'Assumptions & Log'!$F$15,'Assumptions & Log'!$F$17)) -> 562.74272 | J11: =I11*(1+IF(J3<'Assumptions & Log'!$F$16,'Assumptions & Log'!$F$15,'Assumptions & Log'!$F$17)) -> 565.55643 | K11: =J11*(1+IF(K3<'Assumptions & Log'!$F$16,'Assumptions & Log'!$F$15,'Assumptions & Log'!$F$17)) -> 568.38421 | ... N11: =M11*(1+IF(N3<'Assumptions & Log'!$F$16,'Assumptions & Log'!$F$15,'Assumptions & Log'!$F$17)) -> 576.95268
B12: Blended paid CAC — seasonality-adjusted, ₹ | C12: =MAX(C11/C7,300) -> 674.13613 | D12: =MAX(D11/D7,300) -> 733.49798 | E12: =MAX(E11/E7,300) -> 711.77697 | F12: =MAX(F11/F7,300) -> 630.58042 | G12: =MAX(G11/G7,300) -> 655.47908 | H12: =MAX(H11/H7,300) -> 776.79954 | I12: =MAX(I11/I7,300) -> 750.32362 | J12: =MAX(J11/J7,300) -> 766.85618 | ... N12: =MAX(N11/N7,300) -> 576.95268
B13: New customers — paid | C13: =C10/C12 -> 170.58869 | D13: =D10/D12 -> 164.62213 | E13: =E10/E12 -> 178.12813 | F13: =F10/F12 -> 211.118 | G13: =G10/G12 -> 213.25352 | H13: =H10/H12 -> 188.94499 | I13: =I10/I12 -> 205.39271 | J13: =J10/J12 -> 211.0129 | ... N13: =N10/N12 -> 416.08046
B14: New customers — organic/referral | C14: ='Assumptions & Log'!$F$18*'Assumptions & Log'!$F$8+'Assumptions & Log'!$F$19*C7 -> 33.559833 | D14: ='Assumptions & Log'!$F$18*C16+'Assumptions & Log'!$F$19*D7 -> 37.921825 | E14: ='Assumptions & Log'!$F$18*D16+'Assumptions & Log'!$F$19*E7 -> 44.426389 | F14: ='Assumptions & Log'!$F$18*E16+'Assumptions & Log'!$F$19*F7 -> 53.262083 | G14: ='Assumptions & Log'!$F$18*F16+'Assumptions & Log'!$F$19*G7 -> 59.935558 | H14: ='Assumptions & Log'!$F$18*G16+'Assumptions & Log'!$F$19*H7 -> 64.355686 | I14: ='Assumptions & Log'!$F$18*H16+'Assumptions & Log'!$F$19*I7 -> 72.177271 | J14: ='Assumptions & Log'!$F$18*I16+'Assumptions & Log'!$F$19*J7 -> 79.63673 | K14: ='Assumptions & Log'!$F$18*J16+'Assumptions & Log'!$F$19*K7 -> 89.858254 | ... N14: ='Assumptions & Log'!$F$18*M16+'Assumptions & Log'!$F$19*N7 -> 128.76903
B15: New first-time customers (total) | C15: =C13+C14 -> 204.14853 | D15: =D13+D14 -> 202.54396 | E15: =E13+E14 -> 222.55452 | F15: =F13+F14 -> 264.38008 | G15: =G13+G14 -> 273.18908 | H15: =H13+H14 -> 253.30067 | I15: =I13+I14 -> 277.56998 | J15: =J13+J14 -> 290.64963 | ... N15: =N13+N14 -> 544.84949
B16: Cumulative D2C customers (end of month) | C16: ='Assumptions & Log'!$F$8+C15 -> 692.14853 | D16: =C16+D15 -> 894.69248 | E16: =D16+E15 -> 1117.247 | F16: =E16+F15 -> 1381.6271 | G16: =F16+G15 -> 1654.8162 | H16: =G16+H15 -> 1908.1168 | I16: =H16+I15 -> 2185.6868 | J16: =I16+J15 -> 2476.3364 | K16: =J16+K15 -> 2811.5668 | ... N16: =M16+N15 -> 4250.8863
B18: RETENTION & SUBSCRIPTION
B19: Repeat-eligible pool (customers acquired 1-2 mo ago) | C19: =0 -> 0 | D19: =C15 -> 204.14853 | E19: =SUM(C15:D15) -> 406.69248 | F19: =SUM(D15:E15) -> 425.09847 | G19: =SUM(E15:F15) -> 486.9346 | H19: =SUM(F15:G15) -> 537.56915 | I19: =SUM(G15:H15) -> 526.48975 | J19: =SUM(H15:I15) -> 530.87065 | K19: =SUM(I15:J15) -> 568.21961 | L19: =SUM(J15:K15) -> 625.88 | ... N19: =SUM(L15:M15) -> 894.47005
B20: Monthly repeat-purchase probability | C20: ='Assumptions & Log'!$F$20+('Assumptions & Log'!$F$21-'Assumptions & Log'!$F$20)*C3/11 -> 0.16 | D20: ='Assumptions & Log'!$F$20+('Assumptions & Log'!$F$21-'Assumptions & Log'!$F$20)*D3/11 -> 0.16727273 | E20: ='Assumptions & Log'!$F$20+('Assumptions & Log'!$F$21-'Assumptions & Log'!$F$20)*E3/11 -> 0.17454545 | F20: ='Assumptions & Log'!$F$20+('Assumptions & Log'!$F$21-'Assumptions & Log'!$F$20)*F3/11 -> 0.18181818 | G20: ='Assumptions & Log'!$F$20+('Assumptions & Log'!$F$21-'Assumptions & Log'!$F$20)*G3/11 -> 0.18909091 | H20: ='Assumptions & Log'!$F$20+('Assumptions & Log'!$F$21-'Assumptions & Log'!$F$20)*H3/11 -> 0.19636364 | I20: ='Assumptions & Log'!$F$20+('Assumptions & Log'!$F$21-'Assumptions & Log'!$F$20)*I3/11 -> 0.20363636 | J20: ='Assumptions & Log'!$F$20+('Assumptions & Log'!$F$21-'Assumptions & Log'!$F$20)*J3/11 -> 0.21090909 | ... N20: ='Assumptions & Log'!$F$20+('Assumptions & Log'!$F$21-'Assumptions & Log'!$F$20)*N3/11 -> 0.24
B21: Repeat orders | C21: =C19*C20 -> 0 | D21: =D19*D20 -> 34.148481 | E21: =E19*E20 -> 70.986324 | F21: =F19*F20 -> 77.290632 | G21: =G19*G20 -> 92.074905 | H21: =H19*H20 -> 105.55903 | I21: =I19*I20 -> 107.21246 | J21: =J19*J20 -> 111.96545 | ... N21: =N19*N20 -> 214.67281
B22: Share of new customers -> Subscribe&Save | C22: ='Assumptions & Log'!$F$22+('Assumptions & Log'!$F$23-'Assumptions & Log'!$F$22)*C3/11 -> 0.09 | D22: ='Assumptions & Log'!$F$22+('Assumptions & Log'!$F$23-'Assumptions & Log'!$F$22)*D3/11 -> 0.10363636 | E22: ='Assumptions & Log'!$F$22+('Assumptions & Log'!$F$23-'Assumptions & Log'!$F$22)*E3/11 -> 0.11727273 | F22: ='Assumptions & Log'!$F$22+('Assumptions & Log'!$F$23-'Assumptions & Log'!$F$22)*F3/11 -> 0.13090909 | G22: ='Assumptions & Log'!$F$22+('Assumptions & Log'!$F$23-'Assumptions & Log'!$F$22)*G3/11 -> 0.14454545 | H22: ='Assumptions & Log'!$F$22+('Assumptions & Log'!$F$23-'Assumptions & Log'!$F$22)*H3/11 -> 0.15818182 | I22: ='Assumptions & Log'!$F$22+('Assumptions & Log'!$F$23-'Assumptions & Log'!$F$22)*I3/11 -> 0.17181818 | J22: ='Assumptions & Log'!$F$22+('Assumptions & Log'!$F$23-'Assumptions & Log'!$F$22)*J3/11 -> 0.18545455 | ... N22: ='Assumptions & Log'!$F$22+('Assumptions & Log'!$F$23-'Assumptions & Log'!$F$22)*N3/11 -> 0.24
B23: New subscribers | C23: =C15*C22 -> 18.373367 | D23: =D15*D22 -> 20.990919 | E23: =E15*E22 -> 26.099575 | F23: =F15*F22 -> 34.609756 | G23: =G15*G22 -> 39.488239 | H23: =H15*H22 -> 40.067561 | I23: =I15*I22 -> 47.691569 | J23: =J15*J22 -> 53.902296 | ... N23: =N15*N22 -> 130.76388
B24: Active subscribers (end of month) | C24: ='Assumptions & Log'!$F$9*'Assumptions & Log'!$F$24+C23 -> 55.973367 | D24: =C24*'Assumptions & Log'!$F$24+D23 -> 65.769613 | E24: =D24*'Assumptions & Log'!$F$24+E23 -> 78.715266 | F24: =E24*'Assumptions & Log'!$F$24+F23 -> 97.581968 | G24: =F24*'Assumptions & Log'!$F$24+G23 -> 117.55381 | H24: =G24*'Assumptions & Log'!$F$24+H23 -> 134.11061 | I24: =H24*'Assumptions & Log'!$F$24+I23 -> 154.98006 | J24: =I24*'Assumptions & Log'!$F$24+J23 -> 177.88634 | K24: =J24*'Assumptions & Log'!$F$24+K23 -> 209.05039 | ... N24: =M24*'Assumptions & Log'!$F$24+N23 -> 381.45802
B25: Subscription orders | C25: =C24 -> 55.973367 | D25: =D24 -> 65.769613 | E25: =E24 -> 78.715266 | F25: =F24 -> 97.581968 | G25: =G24 -> 117.55381 | H25: =H24 -> 134.11061 | I25: =I24 -> 154.98006 | J25: =J24 -> 177.88634 | ... N25: =N24 -> 381.45802
B27: REVENUE
B28: D2C orders (first + repeat + subscription) | C28: =C15+C21+C25 -> 260.12189 | D28: =D15+D21+D25 -> 302.46205 | E28: =E15+E21+E25 -> 372.25611 | F28: =F15+F21+F25 -> 439.25268 | G28: =G15+G21+G25 -> 482.81779 | H28: =H15+H21+H25 -> 492.97032 | I28: =I15+I21+I25 -> 539.76249 | J28: =J15+J21+J25 -> 580.50142 | ... N28: =N15+N21+N25 -> 1140.9803
B29: D2C AOV, ₹ | C29: =829*(1+'Assumptions & Log'!$F$25)^C3 -> 829 | D29: =829*(1+'Assumptions & Log'!$F$25)^D3 -> 838.119 | E29: =829*(1+'Assumptions & Log'!$F$25)^E3 -> 847.33831 | F29: =829*(1+'Assumptions & Log'!$F$25)^F3 -> 856.65903 | G29: =829*(1+'Assumptions & Log'!$F$25)^G3 -> 866.08228 | H29: =829*(1+'Assumptions & Log'!$F$25)^H3 -> 875.60918 | I29: =829*(1+'Assumptions & Log'!$F$25)^I3 -> 885.24089 | J29: =829*(1+'Assumptions & Log'!$F$25)^J3 -> 894.97854 | ... N29: =829*(1+'Assumptions & Log'!$F$25)^N3 -> 935.01212
B30: D2C revenue, ₹ | C30: =C28*C29 -> 215641.05 | D30: =D28*D29 -> 253499.19 | E30: =E28*E29 -> 315426.86 | F30: =F28*F29 -> 376289.77 | G30: =G28*G29 -> 418159.94 | H30: =H28*H29 -> 431649.34 | I30: =I28*I29 -> 477819.83 | J30: =J28*J29 -> 519536.31 | ... N30: =N28*N29 -> 1066830.4
B31: Marketplace (Amazon) orders | C31: =IF(C3>='Assumptions & Log'!$F$26,'Assumptions & Log'!$F$29*(C3-'Assumptions & Log'!$F$26+1)*C7,0) -> 0 | D31: =IF(D3>='Assumptions & Log'!$F$26,'Assumptions & Log'!$F$29*(D3-'Assumptions & Log'!$F$26+1)*D7,0) -> 81.583333 | E31: =IF(E3>='Assumptions & Log'!$F$26,'Assumptions & Log'!$F$29*(E3-'Assumptions & Log'!$F$26+1)*E7,0) -> 170.5 | F31: =IF(F3>='Assumptions & Log'!$F$26,'Assumptions & Log'!$F$29*(F3-'Assumptions & Log'!$F$26+1)*F7,0) -> 290.125 | G31: =IF(G3>='Assumptions & Log'!$F$26,'Assumptions & Log'!$F$29*(G3-'Assumptions & Log'!$F$26+1)*G7,0) -> 374 | H31: =IF(H3>='Assumptions & Log'!$F$26,'Assumptions & Log'!$F$29*(H3-'Assumptions & Log'!$F$26+1)*H7,0) -> 396.45833 | I31: =IF(I3>='Assumptions & Log'!$F$26,'Assumptions & Log'!$F$29*(I3-'Assumptions & Log'!$F$26+1)*I7,0) -> 495 | J31: =IF(J3>='Assumptions & Log'!$F$26,'Assumptions & Log'!$F$29*(J3-'Assumptions & Log'!$F$26+1)*J7,0) -> 567.875 | ... N31: =IF(N3>='Assumptions & Log'!$F$26,'Assumptions & Log'!$F$29*(N3-'Assumptions & Log'!$F$26+1)*N7,0) -> 1210
B32: Marketplace revenue (net of referral fee), ₹ | C32: =C31*'Assumptions & Log'!$F$27*(1-'Assumptions & Log'!$F$28) -> 0 | D32: =D31*'Assumptions & Log'!$F$27*(1-'Assumptions & Log'!$F$28) -> 47155.167 | E32: =E31*'Assumptions & Log'!$F$27*(1-'Assumptions & Log'!$F$28) -> 98549 | F32: =F31*'Assumptions & Log'!$F$27*(1-'Assumptions & Log'!$F$28) -> 167692.25 | G32: =G31*'Assumptions & Log'!$F$27*(1-'Assumptions & Log'!$F$28) -> 216172 | H32: =H31*'Assumptions & Log'!$F$27*(1-'Assumptions & Log'!$F$28) -> 229152.92 | I32: =I31*'Assumptions & Log'!$F$27*(1-'Assumptions & Log'!$F$28) -> 286110 | J32: =J31*'Assumptions & Log'!$F$27*(1-'Assumptions & Log'!$F$28) -> 328231.75 | ... N32: =N31*'Assumptions & Log'!$F$27*(1-'Assumptions & Log'!$F$28) -> 699380
B33: Quick-commerce (Blinkit) orders | C33: =IF(C3>='Assumptions & Log'!$F$30,'Assumptions & Log'!$F$33*(C3-'Assumptions & Log'!$F$30+1)*C7,0) -> 0 | D33: =IF(D3>='Assumptions & Log'!$F$30,'Assumptions & Log'!$F$33*(D3-'Assumptions & Log'!$F$30+1)*D7,0) -> 0 | E33: =IF(E3>='Assumptions & Log'!$F$30,'Assumptions & Log'!$F$33*(E3-'Assumptions & Log'!$F$30+1)*E7,0) -> 69.75 | F33: =IF(F3>='Assumptions & Log'!$F$30,'Assumptions & Log'!$F$33*(F3-'Assumptions & Log'!$F$30+1)*F7,0) -> 158.25 | G33: =IF(G3>='Assumptions & Log'!$F$30,'Assumptions & Log'!$F$33*(G3-'Assumptions & Log'!$F$30+1)*G7,0) -> 229.5 | H33: =IF(H3>='Assumptions & Log'!$F$30,'Assumptions & Log'!$F$33*(H3-'Assumptions & Log'!$F$30+1)*H7,0) -> 259.5 | I33: =IF(I3>='Assumptions & Log'!$F$30,'Assumptions & Log'!$F$33*(I3-'Assumptions & Log'!$F$30+1)*I7,0) -> 337.5 | J33: =IF(J3>='Assumptions & Log'!$F$30,'Assumptions & Log'!$F$33*(J3-'Assumptions & Log'!$F$30+1)*J7,0) -> 398.25 | ... N33: =IF(N3>='Assumptions & Log'!$F$30,'Assumptions & Log'!$F$33*(N3-'Assumptions & Log'!$F$30+1)*N7,0) -> 900
B34: Quick-commerce revenue (net of trade margin), ₹ | C34: =C33*'Assumptions & Log'!$F$31*(1-'Assumptions & Log'!$F$32) -> 0 | D34: =D33*'Assumptions & Log'!$F$31*(1-'Assumptions & Log'!$F$32) -> 0 | E34: =E33*'Assumptions & Log'!$F$31*(1-'Assumptions & Log'!$F$32) -> 29016 | F34: =F33*'Assumptions & Log'!$F$31*(1-'Assumptions & Log'!$F$32) -> 65832 | G34: =G33*'Assumptions & Log'!$F$31*(1-'Assumptions & Log'!$F$32) -> 95472 | H34: =H33*'Assumptions & Log'!$F$31*(1-'Assumptions & Log'!$F$32) -> 107952 | I34: =I33*'Assumptions & Log'!$F$31*(1-'Assumptions & Log'!$F$32) -> 140400 | J34: =J33*'Assumptions & Log'!$F$31*(1-'Assumptions & Log'!$F$32) -> 165672 | ... N34: =N33*'Assumptions & Log'!$F$31*(1-'Assumptions & Log'!$F$32) -> 374400
B35: TOTAL NET REVENUE (MRR), ₹ | C35: =C30+C32+C34 -> 215641.05 | D35: =D30+D32+D34 -> 300654.36 | E35: =E30+E32+E34 -> 442991.86 | F35: =F30+F32+F34 -> 609814.02 | G35: =G30+G32+G34 -> 729803.94 | H35: =H30+H32+H34 -> 768754.26 | I35: =I30+I32+I34 -> 904329.83 | J35: =J30+J32+J34 -> 1013440.1 | ... N35: =N30+N32+N34 -> 2140610.4
B37: OPS: CANS & CAPACITY
B38: Cans per D2C order | C38: =6.2+1.4*C3/11 -> 6.2 | D38: =6.2+1.4*D3/11 -> 6.3272727 | E38: =6.2+1.4*E3/11 -> 6.4545455 | F38: =6.2+1.4*F3/11 -> 6.5818182 | G38: =6.2+1.4*G3/11 -> 6.7090909 | H38: =6.2+1.4*H3/11 -> 6.8363636 | I38: =6.2+1.4*I3/11 -> 6.9636364 | J38: =6.2+1.4*J3/11 -> 7.0909091 | ... N38: =6.2+1.4*N3/11 -> 7.6
B39: Cans required | C39: =C28*C38+C31*5.5+C33*3.5 -> 1612.7557 | D39: =D28*D38+D31*5.5+D33*3.5 -> 2362.4682 | E39: =E28*E38+E31*5.5+E33*3.5 -> 3584.619 | F39: =F28*F38+F31*5.5+F33*3.5 -> 5040.6438 | G39: =G28*G38+G31*5.5+G33*3.5 -> 6099.5185 | H39: =H28*H38+H31*5.5+H33*3.5 -> 6458.8952 | I39: =I28*I38+I31*5.5+I33*3.5 -> 7662.4597 | J39: =J28*J38+J31*5.5+J33*3.5 -> 8633.4703 | ... N39: =N28*N38+N31*5.5+N33*3.5 -> 18476.45
B40: Capacity ceiling (cans/month) | C40: ='Assumptions & Log'!$F$10+IF(C3>='Assumptions & Log'!$F$34+'Assumptions & Log'!$F$35,48000,0)+IF(C3>='Assumptions & Log'!$F$36+'Assumptions & Log'!$F$37,48000,0) -> 48000 | D40: ='Assumptions & Log'!$F$10+IF(D3>='Assumptions & Log'!$F$34+'Assumptions & Log'!$F$35,48000,0)+IF(D3>='Assumptions & Log'!$F$36+'Assumptions & Log'!$F$37,48000,0) -> 48000 | E40: ='Assumptions & Log'!$F$10+IF(E3>='Assumptions & Log'!$F$34+'Assumptions & Log'!$F$35,48000,0)+IF(E3>='Assumptions & Log'!$F$36+'Assumptions & Log'!$F$37,48000,0) -> 48000 | F40: ='Assumptions & Log'!$F$10+IF(F3>='Assumptions & Log'!$F$34+'Assumptions & Log'!$F$35,48000,0)+IF(F3>='Assumptions & Log'!$F$36+'Assumptions & Log'!$F$37,48000,0) -> 96000 | G40: ='Assumptions & Log'!$F$10+IF(G3>='Assumptions & Log'!$F$34+'Assumptions & Log'!$F$35,48000,0)+IF(G3>='Assumptions & Log'!$F$36+'Assumptions & Log'!$F$37,48000,0) -> 96000 | H40: ='Assumptions & Log'!$F$10+IF(H3>='Assumptions & Log'!$F$34+'Assumptions & Log'!$F$35,48000,0)+IF(H3>='Assumptions & Log'!$F$36+'Assumptions & Log'!$F$37,48000,0) -> 96000 | I40: ='Assumptions & Log'!$F$10+IF(I3>='Assumptions & Log'!$F$34+'Assumptions & Log'!$F$35,48000,0)+IF(I3>='Assumptions & Log'!$F$36+'Assumptions & Log'!$F$37,48000,0) -> 96000 | J40: ='Assumptions & Log'!$F$10+IF(J3>='Assumptions & Log'!$F$34+'Assumptions & Log'!$F$35,48000,0)+IF(J3>='Assumptions & Log'!$F$36+'Assumptions & Log'!$F$37,48000,0) -> 96000 | ... N40: ='Assumptions & Log'!$F$10+IF(N3>='Assumptions & Log'!$F$34+'Assumptions & Log'!$F$35,48000,0)+IF(N3>='Assumptions & Log'!$F$36+'Assumptions & Log'!$F$37,48000,0) -> 144000
B41: Capacity headroom (+) / shortfall (-) | C41: =C40-C39 -> 46387.244 | D41: =D40-D39 -> 45637.532 | E41: =E40-E39 -> 44415.381 | F41: =F40-F39 -> 90959.356 | G41: =G40-G39 -> 89900.482 | H41: =H40-H39 -> 89541.105 | I41: =I40-I39 -> 88337.54 | J41: =J40-J39 -> 87366.53 | ... N41: =N40-N39 -> 125523.55
B43: CONTRIBUTION MARGIN
B44: COGS per can, ₹ | C44: ='Assumptions & Log'!$F$41+('Assumptions & Log'!$F$42-'Assumptions & Log'!$F$41)*C3/11 -> 52 | D44: ='Assumptions & Log'!$F$41+('Assumptions & Log'!$F$42-'Assumptions & Log'!$F$41)*D3/11 -> 51.545455 | E44: ='Assumptions & Log'!$F$41+('Assumptions & Log'!$F$42-'Assumptions & Log'!$F$41)*E3/11 -> 51.090909 | F44: ='Assumptions & Log'!$F$41+('Assumptions & Log'!$F$42-'Assumptions & Log'!$F$41)*F3/11 -> 50.636364 | G44: ='Assumptions & Log'!$F$41+('Assumptions & Log'!$F$42-'Assumptions & Log'!$F$41)*G3/11 -> 50.181818 | H44: ='Assumptions & Log'!$F$41+('Assumptions & Log'!$F$42-'Assumptions & Log'!$F$41)*H3/11 -> 49.727273 | I44: ='Assumptions & Log'!$F$41+('Assumptions & Log'!$F$42-'Assumptions & Log'!$F$41)*I3/11 -> 49.272727 | J44: ='Assumptions & Log'!$F$41+('Assumptions & Log'!$F$42-'Assumptions & Log'!$F$41)*J3/11 -> 48.818182 | ... N44: ='Assumptions & Log'!$F$41+('Assumptions & Log'!$F$42-'Assumptions & Log'!$F$41)*N3/11 -> 47
B45: COGS, ₹ | C45: =C39*C44 -> 83863.298 | D45: =D39*D44 -> 121774.5 | E45: =E39*E44 -> 183141.44 | F45: =F39*F44 -> 255239.87 | G45: =G39*G44 -> 306084.93 | H45: =H39*H44 -> 321183.24 | I45: =I39*I44 -> 377550.29 | J45: =J39*J44 -> 421470.32 | ... N45: =N39*N44 -> 868393.17
B46: Shipping per order, ₹ | C46: ='Assumptions & Log'!$F$43+('Assumptions & Log'!$F$44-'Assumptions & Log'!$F$43)*C3/11 -> 76 | D46: ='Assumptions & Log'!$F$43+('Assumptions & Log'!$F$44-'Assumptions & Log'!$F$43)*D3/11 -> 74.909091 | E46: ='Assumptions & Log'!$F$43+('Assumptions & Log'!$F$44-'Assumptions & Log'!$F$43)*E3/11 -> 73.818182 | F46: ='Assumptions & Log'!$F$43+('Assumptions & Log'!$F$44-'Assumptions & Log'!$F$43)*F3/11 -> 72.727273 | G46: ='Assumptions & Log'!$F$43+('Assumptions & Log'!$F$44-'Assumptions & Log'!$F$43)*G3/11 -> 71.636364 | H46: ='Assumptions & Log'!$F$43+('Assumptions & Log'!$F$44-'Assumptions & Log'!$F$43)*H3/11 -> 70.545455 | I46: ='Assumptions & Log'!$F$43+('Assumptions & Log'!$F$44-'Assumptions & Log'!$F$43)*I3/11 -> 69.454545 | J46: ='Assumptions & Log'!$F$43+('Assumptions & Log'!$F$44-'Assumptions & Log'!$F$43)*J3/11 -> 68.363636 | ... N46: ='Assumptions & Log'!$F$43+('Assumptions & Log'!$F$44-'Assumptions & Log'!$F$43)*N3/11 -> 64
...

Sheet Weekly Rollout
A1: WEEKLY ROLLOUT — 52 WEEKS (Jul 1, 2026 – Jun 29, 2027)
A2: Each week = its month's Monthly Engine total x a within-month weight (weights sum to 1 -> weekly rows always tie back to the monthly engine exactly). Only new-customer acquisition + total revenue carry the weekly weighting; capacity is shown as an even monthly split for headroom-checking.
A4: Wk | B4: Start | C4: End | D4: Month | E4: Wk wt | F4: New Paid Ord | G4: New Org Ord | H4: D2C Orders | I4: Mkt+QC Ord | J4: Total Orders | K4: AOV ₹ | L4: Net Revenue ₹ | M4: Cans Req'd | N4: Capacity/wk | O4: Headroom | P4: CM1 ₹ | Q4: EBITDA (flow) ₹ | R4: Event note
A5: F1 | B5: 46204 | C5: 46210 | D5: Jul-26 | E5: 0.25 | F5: =INDEX('Monthly Engine'!$C$13:$N$13,MATCH($D5,'Monthly Engine'!$C$4:$N$4,0))*$E5 -> 42.647173 | G5: =INDEX('Monthly Engine'!$C$14:$N$14,MATCH($D5,'Monthly Engine'!$C$4:$N$4,0))*$E5 -> 8.3899583 | H5: =INDEX('Monthly Engine'!$C$28:$N$28,MATCH($D5,'Monthly Engine'!$C$4:$N$4,0))*$E5 -> 65.030473 | I5: =(INDEX('Monthly Engine'!$C$31:$N$31,MATCH($D5,'Monthly Engine'!$C$4:$N$4,0))+INDEX('Monthly Engine'!$C$33:$N$33,MATCH($D5,'Monthly Engine'!$C$4:$N$4,0)))*$E5 -> 0 | J5: =H5+I5 -> 65.030473 | K5: =INDEX('Monthly Engine'!$C$29:$N$29,MATCH($D5,'Monthly Engine'!$C$4:$N$4,0)) -> 829 | L5: =INDEX('Monthly Engine'!$C$35:$N$35,MATCH($D5,'Monthly Engine'!$C$4:$N$4,0))*$E5 -> 53910.262 | M5: =INDEX('Monthly Engine'!$C$39:$N$39,MATCH($D5,'Monthly Engine'!$C$4:$N$4,0))*$E5 -> 403.18893 | N5: =INDEX('Monthly Engine'!$C$40:$N$40,MATCH($D5,'Monthly Engine'!$C$4:$N$4,0))/4 -> 12000 | O5: =N5-M5 -> 11596.811 | P5: =INDEX('Monthly Engine'!$C$50:$N$50,MATCH($D5,'Monthly Engine'!$C$4:$N$4,0))*$E5 -> 27470.172 | Q5: =INDEX('Monthly Engine'!$C$60:$N$60,MATCH($D5,'Monthly Engine'!$C$4:$N$4,0))*$E5 -> -40779.828
A6: F2 | B6: 46211 | C6: 46217 | D6: Jul-26 | E6: 0.25 | F6: =INDEX('Monthly Engine'!$C$13:$N$13,MATCH($D6,'Monthly Engine'!$C$4:$N$4,0))*$E6 -> 42.647173 | G6: =INDEX('Monthly Engine'!$C$14:$N$14,MATCH($D6,'Monthly Engine'!$C$4:$N$4,0))*$E6 -> 8.3899583 | H6: =INDEX('Monthly Engine'!$C$28:$N$28,MATCH($D6,'Monthly Engine'!$C$4:$N$4,0))*$E6 -> 65.030473 | I6: =(INDEX('Monthly Engine'!$C$31:$N$31,MATCH($D6,'Monthly Engine'!$C$4:$N$4,0))+INDEX('Monthly Engine'!$C$33:$N$33,MATCH($D6,'Monthly Engine'!$C$4:$N$4,0)))*$E6 -> 0 | J6: =H6+I6 -> 65.030473 | K6: =INDEX('Monthly Engine'!$C$29:$N$29,MATCH($D6,'Monthly Engine'!$C$4:$N$4,0)) -> 829 | L6: =INDEX('Monthly Engine'!$C$35:$N$35,MATCH($D6,'Monthly Engine'!$C$4:$N$4,0))*$E6 -> 53910.262 | M6: =INDEX('Monthly Engine'!$C$39:$N$39,MATCH($D6,'Monthly Engine'!$C$4:$N$4,0))*$E6 -> 403.18893 | N6: =INDEX('Monthly Engine'!$C$40:$N$40,MATCH($D6,'Monthly Engine'!$C$4:$N$4,0))/4 -> 12000 | O6: =N6-M6 -> 11596.811 | P6: =INDEX('Monthly Engine'!$C$50:$N$50,MATCH($D6,'Monthly Engine'!$C$4:$N$4,0))*$E6 -> 27470.172 | Q6: =INDEX('Monthly Engine'!$C$60:$N$60,MATCH($D6,'Monthly Engine'!$C$4:$N$4,0))*$E6 -> -40779.828
A7: F3 | B7: 46218 | C7: 46224 | D7: Jul-26 | E7: 0.25 | F7: =INDEX('Monthly Engine'!$C$13:$N$13,MATCH($D7,'Monthly Engine'!$C$4:$N$4,0))*$E7 -> 42.647173 | G7: =INDEX('Monthly Engine'!$C$14:$N$14,MATCH($D7,'Monthly Engine'!$C$4:$N$4,0))*$E7 -> 8.3899583 | H7: =INDEX('Monthly Engine'!$C$28:$N$28,MATCH($D7,'Monthly Engine'!$C$4:$N$4,0))*$E7 -> 65.030473 | I7: =(INDEX('Monthly Engine'!$C$31:$N$31,MATCH($D7,'Monthly Engine'!$C$4:$N$4,0))+INDEX('Monthly Engine'!$C$33:$N$33,MATCH($D7,'Monthly Engine'!$C$4:$N$4,0)))*$E7 -> 0 | J7: =H7+I7 -> 65.030473 | K7: =INDEX('Monthly Engine'!$C$29:$N$29,MATCH($D7,'Monthly Engine'!$C$4:$N$4,0)) -> 829 | L7: =INDEX('Monthly Engine'!$C$35:$N$35,MATCH($D7,'Monthly Engine'!$C$4:$N$4,0))*$E7 -> 53910.262 | M7: =INDEX('Monthly Engine'!$C$39:$N$39,MATCH($D7,'Monthly Engine'!$C$4:$N$4,0))*$E7 -> 403.18893 | N7: =INDEX('Monthly Engine'!$C$40:$N$40,MATCH($D7,'Monthly Engine'!$C$4:$N$4,0))/4 -> 12000 | O7: =N7-M7 -> 11596.811 | P7: =INDEX('Monthly Engine'!$C$50:$N$50,MATCH($D7,'Monthly Engine'!$C$4:$N$4,0))*$E7 -> 27470.172 | Q7: =INDEX('Monthly Engine'!$C$60:$N$60,MATCH($D7,'Monthly Engine'!$C$4:$N$4,0))*$E7 -> -40779.828
A8: F4 | B8: 46225 | C8: 46231 | D8: Jul-26 | E8: 0.25 | F8: =INDEX('Monthly Engine'!$C$13:$N$13,MATCH($D8,'Monthly Engine'!$C$4:$N$4,0))*$E8 -> 42.647173 | G8: =INDEX('Monthly Engine'!$C$14:$N$14,MATCH($D8,'Monthly Engine'!$C$4:$N$4,0))*$E8 -> 8.3899583 | H8: =INDEX('Monthly Engine'!$C$28:$N$28,MATCH($D8,'Monthly Engine'!$C$4:$N$4,0))*$E8 -> 65.030473 | I8: =(INDEX('Monthly Engine'!$C$31:$N$31,MATCH($D8,'Monthly Engine'!$C$4:$N$4,0))+INDEX('Monthly Engine'!$C$33:$N$33,MATCH($D8,'Monthly Engine'!$C$4:$N$4,0)))*$E8 -> 0 | J8: =H8+I8 -> 65.030473 | K8: =INDEX('Monthly Engine'!$C$29:$N$29,MATCH($D8,'Monthly Engine'!$C$4:$N$4,0)) -> 829 | L8: =INDEX('Monthly Engine'!$C$35:$N$35,MATCH($D8,'Monthly Engine'!$C$4:$N$4,0))*$E8 -> 53910.262 | M8: =INDEX('Monthly Engine'!$C$39:$N$39,MATCH($D8,'Monthly Engine'!$C$4:$N$4,0))*$E8 -> 403.18893 | N8: =INDEX('Monthly Engine'!$C$40:$N$40,MATCH($D8,'Monthly Engine'!$C$4:$N$4,0))/4 -> 12000 | O8: =N8-M8 -> 11596.811 | P8: =INDEX('Monthly Engine'!$C$50:$N$50,MATCH($D8,'Monthly Engine'!$C$4:$N$4,0))*$E8 -> 27470.172 | Q8: =INDEX('Monthly Engine'!$C$60:$N$60,MATCH($D8,'Monthly Engine'!$C$4:$N$4,0))*$E8 -> -40779.828
A9: F5 | B9: 46232 | C9: 46238 | D9: Aug-26 | E9: 0.2 | F9: =INDEX('Monthly Engine'!$C$13:$N$13,MATCH($D9,'Monthly Engine'!$C$4:$N$4,0))*$E9 -> 32.924426 | G9: =INDEX('Monthly Engine'!$C$14:$N$14,MATCH($D9,'Monthly Engine'!$C$4:$N$4,0))*$E9 -> 7.5843651 | H9: =INDEX('Monthly Engine'!$C$28:$N$28,MATCH($D9,'Monthly Engine'!$C$4:$N$4,0))*$E9 -> 60.49241 | I9: =(INDEX('Monthly Engine'!$C$31:$N$31,MATCH($D9,'Monthly Engine'!$C$4:$N$4,0))+INDEX('Monthly Engine'!$C$33:$N$33,MATCH($D9,'Monthly Engine'!$C$4:$N$4,0)))*$E9 -> 16.316667 | J9: =H9+I9 -> 76.809077 | K9: =INDEX('Monthly Engine'!$C$29:$N$29,MATCH($D9,'Monthly Engine'!$C$4:$N$4,0)) -> 838.119 | L9: =INDEX('Monthly Engine'!$C$35:$N$35,MATCH($D9,'Monthly Engine'!$C$4:$N$4,0))*$E9 -> 60130.871 | M9: =INDEX('Monthly Engine'!$C$39:$N$39,MATCH($D9,'Monthly Engine'!$C$4:$N$4,0))*$E9 -> 472.49364 | N9: =INDEX('Monthly Engine'!$C$40:$N$40,MATCH($D9,'Monthly Engine'!$C$4:$N$4,0))/5 -> 9600 | O9: =N9-M9 -> 9127.5064 | P9: =INDEX('Monthly Engine'!$C$50:$N$50,MATCH($D9,'Monthly Engine'!$C$4:$N$4,0))*$E9 -> 29790.303 | Q9: =INDEX('Monthly Engine'!$C$60:$N$60,MATCH($D9,'Monthly Engine'!$C$4:$N$4,0))*$E9 -> -25989.697
A10: F6 | B10: 46239 | C10: 46245 | D10: Aug-26 | E10: 0.2 | F10: =INDEX('Monthly Engine'!$C$13:$N$13,MATCH($D10,'Monthly Engine'!$C$4:$N$4,0))*$E10 -> 32.924426 | G10: =INDEX('Monthly Engine'!$C$14:$N$14,MATCH($D10,'Monthly Engine'!$C$4:$N$4,0))*$E10 -> 7.5843651 | H10: =INDEX('Monthly Engine'!$C$28:$N$28,MATCH($D10,'Monthly Engine'!$C$4:$N$4,0))*$E10 -> 60.49241 | I10: =(INDEX('Monthly Engine'!$C$31:$N$31,MATCH($D10,'Monthly Engine'!$C$4:$N$4,0))+INDEX('Monthly Engine'!$C$33:$N$33,MATCH($D10,'Monthly Engine'!$C$4:$N$4,0)))*$E10 -> 16.316667 | J10: =H10+I10 -> 76.809077 | K10: =INDEX('Monthly Engine'!$C$29:$N$29,MATCH($D10,'Monthly Engine'!$C$4:$N$4,0)) -> 838.119 | L10: =INDEX('Monthly Engine'!$C$35:$N$35,MATCH($D10,'Monthly Engine'!$C$4:$N$4,0))*$E10 -> 60130.871 | M10: =INDEX('Monthly Engine'!$C$39:$N$39,MATCH($D10,'Monthly Engine'!$C$4:$N$4,0))*$E10 -> 472.49364 | N10: =INDEX('Monthly Engine'!$C$40:$N$40,MATCH($D10,'Monthly Engine'!$C$4:$N$4,0))/5 -> 9600 | O10: =N10-M10 -> 9127.5064 | P10: =INDEX('Monthly Engine'!$C$50:$N$50,MATCH($D10,'Monthly Engine'!$C$4:$N$4,0))*$E10 -> 29790.303 | Q10: =INDEX('Monthly Engine'!$C$60:$N$60,MATCH($D10,'Monthly Engine'!$C$4:$N$4,0))*$E10 -> -25989.697
A11: F7 | B11: 46246 | C11: 46252 | D11: Aug-26 | E11: 0.2 | F11: =INDEX('Monthly Engine'!$C$13:$N$13,MATCH($D11,'Monthly Engine'!$C$4:$N$4,0))*$E11 -> 32.924426 | G11: =INDEX('Monthly Engine'!$C$14:$N$14,MATCH($D11,'Monthly Engine'!$C$4:$N$4,0))*$E11 -> 7.5843651 | H11: =INDEX('Monthly Engine'!$C$28:$N$28,MATCH($D11,'Monthly Engine'!$C$4:$N$4,0))*$E11 -> 60.49241 | I11: =(INDEX('Monthly Engine'!$C$31:$N$31,MATCH($D11,'Monthly Engine'!$C$4:$N$4,0))+INDEX('Monthly Engine'!$C$33:$N$33,MATCH($D11,'Monthly Engine'!$C$4:$N$4,0)))*$E11 -> 16.316667 | J11: =H11+I11 -> 76.809077 | K11: =INDEX('Monthly Engine'!$C$29:$N$29,MATCH($D11,'Monthly Engine'!$C$4:$N$4,0)) -> 838.119 | L11: =INDEX('Monthly Engine'!$C$35:$N$35,MATCH($D11,'Monthly Engine'!$C$4:$N$4,0))*$E11 -> 60130.871 | M11: =INDEX('Monthly Engine'!$C$39:$N$39,MATCH($D11,'Monthly Engine'!$C$4:$N$4,0))*$E11 -> 472.49364 | N11: =INDEX('Monthly Engine'!$C$40:$N$40,MATCH($D11,'Monthly Engine'!$C$4:$N$4,0))/5 -> 9600 | O11: =N11-M11 -> 9127.5064 | P11: =INDEX('Monthly Engine'!$C$50:$N$50,MATCH($D11,'Monthly Engine'!$C$4:$N$4,0))*$E11 -> 29790.303 | Q11: =INDEX('Monthly Engine'!$C$60:$N$60,MATCH($D11,'Monthly Engine'!$C$4:$N$4,0))*$E11 -> -25989.697
A12: F8 | B12: 46253 | C12: 46259 | D12: Aug-26 | E12: 0.2 | F12: =INDEX('Monthly Engine'!$C$13:$N$13,MATCH($D12,'Monthly Engine'!$C$4:$N$4,0))*$E12 -> 32.924426 | G12: =INDEX('Monthly Engine'!$C$14:$N$14,MATCH($D12,'Monthly Engine'!$C$4:$N$4,0))*$E12 -> 7.5843651 | H12: =INDEX('Monthly Engine'!$C$28:$N$28,MATCH($D12,'Monthly Engine'!$C$4:$N$4,0))*$E12 -> 60.49241 | I12: =(INDEX('Monthly Engine'!$C$31:$N$31,MATCH($D12,'Monthly Engine'!$C$4:$N$4,0))+INDEX('Monthly Engine'!$C$33:$N$33,MATCH($D12,'Monthly Engine'!$C$4:$N$4,0)))*$E12 -> 16.316667 | J12: =H12+I12 -> 76.809077 | K12: =INDEX('Monthly Engine'!$C$29:$N$29,MATCH($D12,'Monthly Engine'!$C$4:$N$4,0)) -> 838.119 | L12: =INDEX('Monthly Engine'!$C$35:$N$35,MATCH($D12,'Monthly Engine'!$C$4:$N$4,0))*$E12 -> 60130.871 | M12: =INDEX('Monthly Engine'!$C$39:$N$39,MATCH($D12,'Monthly Engine'!$C$4:$N$4,0))*$E12 -> 472.49364 | N12: =INDEX('Monthly Engine'!$C$40:$N$40,MATCH($D12,'Monthly Engine'!$C$4:$N$4,0))/5 -> 9600 | O12: =N12-M12 -> 9127.5064 | P12: =INDEX('Monthly Engine'!$C$50:$N$50,MATCH($D12,'Monthly Engine'!$C$4:$N$4,0))*$E12 -> 29790.303 | Q12: =INDEX('Monthly Engine'!$C$60:$N$60,MATCH($D12,'Monthly Engine'!$C$4:$N$4,0))*$E12 -> -25989.697
A13: F9 | B13: 46260 | C13: 46266 | D13: Aug-26 | E13: 0.2 | F13: =INDEX('Monthly Engine'!$C$13:$N$13,MATCH($D13,'Monthly Engine'!$C$4:$N$4,0))*$E13 -> 32.924426 | G13: =INDEX('Monthly Engine'!$C$14:$N$14,MATCH($D13,'Monthly Engine'!$C$4:$N$4,0))*$E13 -> 7.5843651 | H13: =INDEX('Monthly Engine'!$C$28:$N$28,MATCH($D13,'Monthly Engine'!$C$4:$N$4,0))*$E13 -> 60.49241 | I13: =(INDEX('Monthly Engine'!$C$31:$N$31,MATCH($D13,'Monthly Engine'!$C$4:$N$4,0))+INDEX('Monthly Engine'!$C$33:$N$33,MATCH($D13,'Monthly Engine'!$C$4:$N$4,0)))*$E13 -> 16.316667 | J13: =H13+I13 -> 76.809077 | K13: =INDEX('Monthly Engine'!$C$29:$N$29,MATCH($D13,'Monthly Engine'!$C$4:$N$4,0)) -> 838.119 | L13: =INDEX('Monthly Engine'!$C$35:$N$35,MATCH($D13,'Monthly Engine'!$C$4:$N$4,0))*$E13 -> 60130.871 | M13: =INDEX('Monthly Engine'!$C$39:$N$39,MATCH($D13,'Monthly Engine'!$C$4:$N$4,0))*$E13 -> 472.49364 | N13: =INDEX('Monthly Engine'!$C$40:$N$40,MATCH($D13,'Monthly Engine'!$C$4:$N$4,0))/5 -> 9600 | O13: =N13-M13 -> 9127.5064 | P13: =INDEX('Monthly Engine'!$C$50:$N$50,MATCH($D13,'Monthly Engine'!$C$4:$N$4,0))*$E13 -> 29790.303 | Q13: =INDEX('Monthly Engine'!$C$60:$N$60,MATCH($D13,'Monthly Engine'!$C$4:$N$4,0))*$E13 -> -25989.697
A14: F10 | B14: 46267 | C14: 46273 | D14: Sep-26 | E14: 0.25 | F14: =INDEX('Monthly Engine'!$C$13:$N$13,MATCH($D14,'Monthly Engine'!$C$4:$N$4,0))*$E14 -> 44.532032 | G14: =INDEX('Monthly Engine'!$C$14:$N$14,MATCH($D14,'Monthly Engine'!$C$4:$N$4,0))*$E14 -> 11.106597 | H14: =INDEX('Monthly Engine'!$C$28:$N$28,MATCH($D14,'Monthly Engine'!$C$4:$N$4,0))*$E14 -> 93.064027 | I14: =(INDEX('Monthly Engine'!$C$31:$N$31,MATCH($D14,'Monthly Engine'!$C$4:$N$4,0))+INDEX('Monthly Engine'!$C$33:$N$33,MATCH($D14,'Monthly Engine'!$C$4:$N$4,0)))*$E14 -> 60.0625 | J14: =H14+I14 -> 153.12653 | K14: =INDEX('Monthly Engine'!$C$29:$N$29,MATCH($D14,'Monthly Engine'!$C$4:$N$4,0)) -> 847.33831 | L14: =INDEX('Monthly Engine'!$C$35:$N$35,MATCH($D14,'Monthly Engine'!$C$4:$N$4,0))*$E14 -> 110747.97 | M14: =INDEX('Monthly Engine'!$C$39:$N$39,MATCH($D14,'Monthly Engine'!$C$4:$N$4,0))*$E14 -> 896.15474 | N14: =INDEX('Monthly Engine'!$C$40:$N$40,MATCH($D14,'Monthly Engine'!$C$4:$N$4,0))/4 -> 12000 | O14: =N14-M14 -> 11103.845 | P14: =INDEX('Monthly Engine'!$C$50:$N$50,MATCH($D14,'Monthly Engine'!$C$4:$N$4,0))*$E14 -> 53918.124 | Q14: =INDEX('Monthly Engine'!$C$60:$N$60,MATCH($D14,'Monthly Engine'!$C$4:$N$4,0))*$E14 -> -27353.751
A15: F11 | B15: 46274 | C15: 46280 | D15: Sep-26 | E15: 0.25 | F15: =INDEX('Monthly Engine'!$C$13:$N$13,MATCH($D15,'Monthly Engine'!$C$4:$N$4,0))*$E15 -> 44.532032 | G15: =INDEX('Monthly Engine'!$C$14:$N$14,MATCH($D15,'Monthly Engine'!$C$4:$N$4,0))*$E15 -> 11.106597 | H15: =INDEX('Monthly Engine'!$C$28:$N$28,MATCH($D15,'Monthly Engine'!$C$4:$N$4,0))*$E15 -> 93.064027 | I15: =(INDEX('Monthly Engine'!$C$31:$N$31,MATCH($D15,'Monthly Engine'!$C$4:$N$4,0))+INDEX('Monthly Engine'!$C$33:$N$33,MATCH($D15,'Monthly Engine'!$C$4:$N$4,0)))*$E15 -> 60.0625 | J15: =H15+I15 -> 153.12653 | K15: =INDEX('Monthly Engine'!$C$29:$N$29,MATCH($D15,'Monthly Engine'!$C$4:$N$4,0)) -> 847.33831 | L15: =INDEX('Monthly Engine'!$C$35:$N$35,MATCH($D15,'Monthly Engine'!$C$4:$N$4,0))*$E15 -> 110747.97 | M15: =INDEX('Monthly Engine'!$C$39:$N$39,MATCH($D15,'Monthly Engine'!$C$4:$N$4,0))*$E15 -> 896.15474 | N15: =INDEX('Monthly Engine'!$C$40:$N$40,MATCH($D15,'Monthly Engine'!$C$4:$N$4,0))/4 -> 12000 | O15: =N15-M15 -> 11103.845 | P15: =INDEX('Monthly Engine'!$C$50:$N$50,MATCH($D15,'Monthly Engine'!$C$4:$N$4,0))*$E15 -> 53918.124 | Q15: =INDEX('Monthly Engine'!$C$60:$N$60,MATCH($D15,'Monthly Engine'!$C$4:$N$4,0))*$E15 -> -27353.751
A16: F12 | B16: 46281 | C16: 46287 | D16: Sep-26 | E16: 0.25 | F16: =INDEX('Monthly Engine'!$C$13:$N$13,MATCH($D16,'Monthly Engine'!$C$4:$N$4,0))*$E16 -> 44.532032 | G16: =INDEX('Monthly Engine'!$C$14:$N$14,MATCH($D16,'Monthly Engine'!$C$4:$N$4,0))*$E16 -> 11.106597 | H16: =INDEX('Monthly Engine'!$C$28:$N$28,MATCH($D16,'Monthly Engine'!$C$4:$N$4,0))*$E16 -> 93.064027 | I16: =(INDEX('Monthly Engine'!$C$31:$N$31,MATCH($D16,'Monthly Engine'!$C$4:$N$4,0))+INDEX('Monthly Engine'!$C$33:$N$33,MATCH($D16,'Monthly Engine'!$C$4:$N$4,0)))*$E16 -> 60.0625 | J16: =H16+I16 -> 153.12653 | K16: =INDEX('Monthly Engine'!$C$29:$N$29,MATCH($D16,'Monthly Engine'!$C$4:$N$4,0)) -> 847.33831 | L16: =INDEX('Monthly Engine'!$C$35:$N$35,MATCH($D16,'Monthly Engine'!$C$4:$N$4,0))*$E16 -> 110747.97 | M16: =INDEX('Monthly Engine'!$C$39:$N$39,MATCH($D16,'Monthly Engine'!$C$4:$N$4,0))*$E16 -> 896.15474 | N16: =INDEX('Monthly Engine'!$C$40:$N$40,MATCH($D16,'Monthly Engine'!$C$4:$N$4,0))/4 -> 12000 | O16: =N16-M16 -> 11103.845 | P16: =INDEX('Monthly Engine'!$C$50:$N$50,MATCH($D16,'Monthly Engine'!$C$4:$N$4,0))*$E16 -> 53918.124 | Q16: =INDEX('Monthly Engine'!$C$60:$N$60,MATCH($D16,'Monthly Engine'!$C$4:$N$4,0))*$E16 -> -27353.751
A17: F13 | B17: 46288 | C17: 46294 | D17: Sep-26 | E17: 0.25 | F17: =INDEX('Monthly Engine'!$C$13:$N$13,MATCH($D17,'Monthly Engine'!$C$4:$N$4,0))*$E17 -> 44.532032 | G17: =INDEX('Monthly Engine'!$C$14:$N$14,MATCH($D17,'Monthly Engine'!$C$4:$N$4,0))*$E17 -> 11.106597 | H17: =INDEX('Monthly Engine'!$C$28:$N$28,MATCH($D17,'Monthly Engine'!$C$4:$N$4,0))*$E17 -> 93.064027 | I17: =(INDEX('Monthly Engine'!$C$31:$N$31,MATCH($D17,'Monthly Engine'!$C$4:$N$4,0))+INDEX('Monthly Engine'!$C$33:$N$33,MATCH($D17,'Monthly Engine'!$C$4:$N$4,0)))*$E17 -> 60.0625 | J17: =H17+I17 -> 153.12653 | K17: =INDEX('Monthly Engine'!$C$29:$N$29,MATCH($D17,'Monthly Engine'!$C$4:$N$4,0)) -> 847.33831 | L17: =INDEX('Monthly Engine'!$C$35:$N$35,MATCH($D17,'Monthly Engine'!$C$4:$N$4,0))*$E17 -> 110747.97 | M17: =INDEX('Monthly Engine'!$C$39:$N$39,MATCH($D17,'Monthly Engine'!$C$4:$N$4,0))*$E17 -> 896.15474 | N17: =INDEX('Monthly Engine'!$C$40:$N$40,MATCH($D17,'Monthly Engine'!$C$4:$N$4,0))/4 -> 12000 | O17: =N17-M17 -> 11103.845 | P17: =INDEX('Monthly Engine'!$C$50:$N$50,MATCH($D17,'Monthly Engine'!$C$4:$N$4,0))*$E17 -> 53918.124 | Q17: =INDEX('Monthly Engine'!$C$60:$N$60,MATCH($D17,'Monthly Engine'!$C$4:$N$4,0))*$E17 -> -27353.751
A18: F14 | B18: 46295 | C18: 46301 | D18: Oct-26 | E18: 0.2 | F18: =INDEX('Monthly Engine'!$C$13:$N$13,MATCH($D18,'Monthly Engine'!$C$4:$N$4,0))*$E18 -> 42.223599 | G18: =INDEX('Monthly Engine'!$C$14:$N$14,MATCH($D18,'Monthly Engine'!$C$4:$N$4,0))*$E18 -> 10.652417 | H18: =INDEX('Monthly Engine'!$C$28:$N$28,MATCH($D18,'Monthly Engine'!$C$4:$N$4,0))*$E18 -> 87.850536 | I18: =(INDEX('Monthly Engine'!$C$31:$N$31,MATCH($D18,'Monthly Engine'!$C$4:$N$4,0))+INDEX('Monthly Engine'!$C$33:$N$33,MATCH($D18,'Monthly Engine'!$C$4:$N$4,0)))*$E18 -> 89.675 | J18: =H18+I18 -> 177.52554 | K18: =INDEX('Monthly Engine'!$C$29:$N$29,MATCH($D18,'Monthly Engine'!$C$4:$N$4,0)) -> 856.65903 | L18: =INDEX('Monthly Engine'!$C$35:$N$35,MATCH($D18,'Monthly Engine'!$C$4:$N$4,0))*$E18 -> 121962.8 | M18: =INDEX('Monthly Engine'!$C$39:$N$39,MATCH($D18,'Monthly Engine'!$C$4:$N$4,0))*$E18 -> 1008.1288 | N18: =INDEX('Monthly Engine'!$C$40:$N$40,MATCH($D18,'Monthly Engine'!$C$4:$N$4,0))/5 -> 19200 | O18: =N18-M18 -> 18191.871 | P18: =INDEX('Monthly Engine'!$C$50:$N$50,MATCH($D18,'Monthly Engine'!$C$4:$N$4,0))*$E18 -> 58796.294 | Q18: =INDEX('Monthly Engine'!$C$60:$N$60,MATCH($D18,'Monthly Engine'!$C$4:$N$4,0))*$E18 -> -7519.0812
A19: F15 | B19: 46302 | C19: 46308 | D19: Oct-26 | E19: 0.2 | F19: =INDEX('Monthly Engine'!$C$13:$N$13,MATCH($D19,'Monthly Engine'!$C$4:$N$4,0))*$E19 -> 42.223599 | G19: =INDEX('Monthly Engine'!$C$14:$N$14,MATCH($D19,'Monthly Engine'!$C$4:$N$4,0))*$E19 -> 10.652417 | H19: =INDEX('Monthly Engine'!$C$28:$N$28,MATCH($D19,'Monthly Engine'!$C$4:$N$4,0))*$E19 -> 87.850536 | I19: =(INDEX('Monthly Engine'!$C$31:$N$31,MATCH($D19,'Monthly Engine'!$C$4:$N$4,0))+INDEX('Monthly Engine'!$C$33:$N$33,MATCH($D19,'Monthly Engine'!$C$4:$N$4,0)))*$E19 -> 89.675 | J19: =H19+I19 -> 177.52554 | K19: =INDEX('Monthly Engine'!$C$29:$N$29,MATCH($D19,'Monthly Engine'!$C$4:$N$4,0)) -> 856.65903 | L19: =INDEX('Monthly Engine'!$C$35:$N$35,MATCH($D19,'Monthly Engine'!$C$4:$N$4,0))*$E19 -> 121962.8 | M19: =INDEX('Monthly Engine'!$C$39:$N$39,MATCH($D19,'Monthly Engine'!$C$4:$N$4,0))*$E19 -> 1008.1288 | N19: =INDEX('Monthly Engine'!$C$40:$N$40,MATCH($D19,'Monthly Engine'!$C$4:$N$4,0))/5 -> 19200 | O19: =N19-M19 -> 18191.871 | P19: =INDEX('Monthly Engine'!$C$50:$N$50,MATCH($D19,'Monthly Engine'!$C$4:$N$4,0))*$E19 -> 58796.294 | Q19: =INDEX('Monthly Engine'!$C$60:$N$60,MATCH($D19,'Monthly Engine'!$C$4:$N$4,0))*$E19 -> -7519.0812
A20: F16 | B20: 46309 | C20: 46315 | D20: Oct-26 | E20: 0.2 | F20: =INDEX('Monthly Engine'!$C$13:$N$13,MATCH($D20,'Monthly Engine'!$C$4:$N$4,0))*$E20 -> 42.223599 | G20: =INDEX('Monthly Engine'!$C$14:$N$14,MATCH($D20,'Monthly Engine'!$C$4:$N$4,0))*$E20 -> 10.652417 | H20: =INDEX('Monthly Engine'!$C$28:$N$28,MATCH($D20,'Monthly Engine'!$C$4:$N$4,0))*$E20 -> 87.850536 | I20: =(INDEX('Monthly Engine'!$C$31:$N$31,MATCH($D20,'Monthly Engine'!$C$4:$N$4,0))+INDEX('Monthly Engine'!$C$33:$N$33,MATCH($D20,'Monthly Engine'!$C$4:$N$4,0)))*$E20 -> 89.675 | J20: =H20+I20 -> 177.52554 | K20: =INDEX('Monthly Engine'!$C$29:$N$29,MATCH($D20,'Monthly Engine'!$C$4:$N$4,0)) -> 856.65903 | L20: =INDEX('Monthly Engine'!$C$35:$N$35,MATCH($D20,'Monthly Engine'!$C$4:$N$4,0))*$E20 -> 121962.8 | M20: =INDEX('Monthly Engine'!$C$39:$N$39,MATCH($D20,'Monthly Engine'!$C$4:$N$4,0))*$E20 -> 1008.1288 | N20: =INDEX('Monthly Engine'!$C$40:$N$40,MATCH($D20,'Monthly Engine'!$C$4:$N$4,0))/5 -> 19200 | O20: =N20-M20 -> 18191.871 | P20: =INDEX('Monthly Engine'!$C$50:$N$50,MATCH($D20,'Monthly Engine'!$C$4:$N$4,0))*$E20 -> 58796.294 | Q20: =INDEX('Monthly Engine'!$C$60:$N$60,MATCH($D20,'Monthly Engine'!$C$4:$N$4,0))*$E20 -> -7519.0812
A21: F17 | B21: 46316 | C21: 46322 | D21: Oct-26 | E21: 0.2 | F21: =INDEX('Monthly Engine'!$C$13:$N$13,MATCH($D21,'Monthly Engine'!$C$4:$N$4,0))*$E21 -> 42.223599 | G21: =INDEX('Monthly Engine'!$C$14:$N$14,MATCH($D21,'Monthly Engine'!$C$4:$N$4,0))*$E21 -> 10.652417 | H21: =INDEX('Monthly Engine'!$C$28:$N$28,MATCH($D21,'Monthly Engine'!$C$4:$N$4,0))*$E21 -> 87.850536 | I21: =(INDEX('Monthly Engine'!$C$31:$N$31,MATCH($D21,'Monthly Engine'!$C$4:$N$4,0))+INDEX('Monthly Engine'!$C$33:$N$33,MATCH($D21,'Monthly Engine'!$C$4:$N$4,0)))*$E21 -> 89.675 | J21: =H21+I21 -> 177.52554 | K21: =INDEX('Monthly Engine'!$C$29:$N$29,MATCH($D21,'Monthly Engine'!$C$4:$N$4,0)) -> 856.65903 | L21: =INDEX('Monthly Engine'!$C$35:$N$35,MATCH($D21,'Monthly Engine'!$C$4:$N$4,0))*$E21 -> 121962.8 | M21: =INDEX('Monthly Engine'!$C$39:$N$39,MATCH($D21,'Monthly Engine'!$C$4:$N$4,0))*$E21 -> 1008.1288 | N21: =INDEX('Monthly Engine'!$C$40:$N$40,MATCH($D21,'Monthly Engine'!$C$4:$N$4,0))/5 -> 19200 | O21: =N21-M21 -> 18191.871 | P21: =INDEX('Monthly Engine'!$C$50:$N$50,MATCH($D21,'Monthly Engine'!$C$4:$N$4,0))*$E21 -> 58796.294 | Q21: =INDEX('Monthly Engine'!$C$60:$N$60,MATCH($D21,'Monthly Engine'!$C$4:$N$4,0))*$E21 -> -7519.0812
A22: F18 | B22: 46323 | C22: 46329 | D22: Oct-26 | E22: 0.2 | F22: =INDEX('Monthly Engine'!$C$13:$N$13,MATCH($D22,'Monthly Engine'!$C$4:$N$4,0))*$E22 -> 42.223599 | G22: =INDEX('Monthly Engine'!$C$14:$N$14,MATCH($D22,'Monthly Engine'!$C$4:$N$4,0))*$E22 -> 10.652417 | H22: =INDEX('Monthly Engine'!$C$28:$N$28,MATCH($D22,'Monthly Engine'!$C$4:$N$4,0))*$E22 -> 87.850536 | I22: =(INDEX('Monthly Engine'!$C$31:$N$31,MATCH($D22,'Monthly Engine'!$C$4:$N$4,0))+INDEX('Monthly Engine'!$C$33:$N$33,MATCH($D22,'Monthly Engine'!$C$4:$N$4,0)))*$E22 -> 89.675 | J22: =H22+I22 -> 177.52554 | K22: =INDEX('Monthly Engine'!$C$29:$N$29,MATCH($D22,'Monthly Engine'!$C$4:$N$4,0)) -> 856.65903 | L22: =INDEX('Monthly Engine'!$C$35:$N$35,MATCH($D22,'Monthly Engine'!$C$4:$N$4,0))*$E22 -> 121962.8 | M22: =INDEX('Monthly Engine'!$C$39:$N$39,MATCH($D22,'Monthly Engine'!$C$4:$N$4,0))*$E22 -> 1008.1288 | N22: =INDEX('Monthly Engine'!$C$40:$N$40,MATCH($D22,'Monthly Engine'!$C$4:$N$4,0))/5 -> 19200 | O22: =N22-M22 -> 18191.871 | P22: =INDEX('Monthly Engine'!$C$50:$N$50,MATCH($D22,'Monthly Engine'!$C$4:$N$4,0))*$E22 -> 58796.294 | Q22: =INDEX('Monthly Engine'!$C$60:$N$60,MATCH($D22,'Monthly Engine'!$C$4:$N$4,0))*$E22 -> -7519.0812
A23: F19 | B23: 46330 | C23: 46336 | D23: Nov-26 | E23: 0.375 | F23: =INDEX('Monthly Engine'!$C$13:$N$13,MATCH($D23,'Monthly Engine'!$C$4:$N$4,0))*$E23 -> 79.970069 | G23: =INDEX('Monthly Engine'!$C$14:$N$14,MATCH($D23,'Monthly Engine'!$C$4:$N$4,0))*$E23 -> 22.475834 | H23: =INDEX('Monthly Engine'!$C$28:$N$28,MATCH($D23,'Monthly Engine'!$C$4:$N$4,0))*$E23 -> 181.05667 | I23: =(INDEX('Monthly Engine'!$C$31:$N$31,MATCH($D23,'Monthly Engine'!$C$4:$N$4,0))+INDEX('Monthly Engine'!$C$33:$N$33,MATCH($D23,'Monthly Engine'!$C$4:$N$4,0)))*$E23 -> 226.3125 | J23: =H23+I23 -> 407.36917 | K23: =INDEX('Monthly Engine'!$C$29:$N$29,MATCH($D23,'Monthly Engine'!$C$4:$N$4,0)) -> 866.08228 | L23: =INDEX('Monthly Engine'!$C$35:$N$35,MATCH($D23,'Monthly Engine'!$C$4:$N$4,0))*$E23 -> 273676.48 | M23: =INDEX('Monthly Engine'!$C$39:$N$39,MATCH($D23,'Monthly Engine'!$C$4:$N$4,0))*$E23 -> 2287.3194 | N23: =INDEX('Monthly Engine'!$C$40:$N$40,MATCH($D23,'Monthly Engine'!$C$4:$N$4,0))/4 -> 24000 | O23: =N23-M23 -> 21712.681 | P23: =INDEX('Monthly Engine'!$C$50:$N$50,MATCH($D23,'Monthly Engine'!$C$4:$N$4,0))*$E23 -> 131928.38 | Q23: =INDEX('Monthly Engine'!$C$60:$N$60,MATCH($D23,'Monthly Engine'!$C$4:$N$4,0))*$E23 -> 5034.6772 | R23: Diwali week (demand nudge)
A24: F20 | B24: 46337 | C24: 46343 | D24: Nov-26 | E24: 0.2083 | F24: =INDEX('Monthly Engine'!$C$13:$N$13,MATCH($D24,'Monthly Engine'!$C$4:$N$4,0))*$E24 -> 44.420708 | G24: =INDEX('Monthly Engine'!$C$14:$N$14,MATCH($D24,'Monthly Engine'!$C$4:$N$4,0))*$E24 -> 12.484577 | H24: =INDEX('Monthly Engine'!$C$28:$N$28,MATCH($D24,'Monthly Engine'!$C$4:$N$4,0))*$E24 -> 100.57095 | I24: =(INDEX('Monthly Engine'!$C$31:$N$31,MATCH($D24,'Monthly Engine'!$C$4:$N$4,0))+INDEX('Monthly Engine'!$C$33:$N$33,MATCH($D24,'Monthly Engine'!$C$4:$N$4,0)))*$E24 -> 125.70905 | J24: =H24+I24 -> 226.28 | K24: =INDEX('Monthly Engine'!$C$29:$N$29,MATCH($D24,'Monthly Engine'!$C$4:$N$4,0)) -> 866.08228 | L24: =INDEX('Monthly Engine'!$C$35:$N$35,MATCH($D24,'Monthly Engine'!$C$4:$N$4,0))*$E24 -> 152018.16 | M24: =INDEX('Monthly Engine'!$C$39:$N$39,MATCH($D24,'Monthly Engine'!$C$4:$N$4,0))*$E24 -> 1270.5297 | N24: =INDEX('Monthly Engine'!$C$40:$N$40,MATCH($D24,'Monthly Engine'!$C$4:$N$4,0))/4 -> 24000 | O24: =N24-M24 -> 22729.47 | P24: =INDEX('Monthly Engine'!$C$50:$N$50,MATCH($D24,'Monthly Engine'!$C$4:$N$4,0))*$E24 -> 73281.82 | Q24: =INDEX('Monthly Engine'!$C$60:$N$60,MATCH($D24,'Monthly Engine'!$C$4:$N$4,0))*$E24 -> 2796.5954
A25: F21 | B25: 46344 | C25: 46350 | D25: Nov-26 | E25: 0.2083 | F25: =INDEX('Monthly Engine'!$C$13:$N$13,MATCH($D25,'Monthly Engine'!$C$4:$N$4,0))*$E25 -> 44.420708 | G25: =INDEX('Monthly Engine'!$C$14:$N$14,MATCH($D25,'Monthly Engine'!$C$4:$N$4,0))*$E25 -> 12.484577 | H25: =INDEX('Monthly Engine'!$C$28:$N$28,MATCH($D25,'Monthly Engine'!$C$4:$N$4,0))*$E25 -> 100.57095 | I25: =(INDEX('Monthly Engine'!$C$31:$N$31,MATCH($D25,'Monthly Engine'!$C$4:$N$4,0))+INDEX('Monthly Engine'!$C$33:$N$33,MATCH($D25,'Monthly Engine'!$C$4:$N$4,0)))*$E25 -> 125.70905 | J25: =H25+I25 -> 226.28 | K25: =INDEX('Monthly Engine'!$C$29:$N$29,MATCH($D25,'Monthly Engine'!$C$4:$N$4,0)) -> 866.08228 | L25: =INDEX('Monthly Engine'!$C$35:$N$35,MATCH($D25,'Monthly Engine'!$C$4:$N$4,0))*$E25 -> 152018.16 | M25: =INDEX('Monthly Engine'!$C$39:$N$39,MATCH($D25,'Monthly Engine'!$C$4:$N$4,0))*$E25 -> 1270.5297 | N25: =INDEX('Monthly Engine'!$C$40:$N$40,MATCH($D25,'Monthly Engine'!$C$4:$N$4,0))/4 -> 24000 | O25: =N25-M25 -> 22729.47 | P25: =INDEX('Monthly Engine'!$C$50:$N$50,MATCH($D25,'Monthly Engine'!$C$4:$N$4,0))*$E25 -> 73281.82 | Q25: =INDEX('Monthly Engine'!$C$60:$N$60,MATCH($D25,'Monthly Engine'!$C$4:$N$4,0))*$E25 -> 2796.5954
